<?xml version="1.0" ?>
<!-- =================================================================================== -->
<!-- |    This document was autogenerated by xacro from segbot_armversion.urdf.xacro   | -->
<!-- |    EDITING THIS FILE BY HAND IS NOT RECOMMENDED                                 | -->
<!-- =================================================================================== -->
<robot name="segbot" xmlns:controller="http://playerstage.sourceforge.net/gazebo/xmlschema/#controller" xmlns:interface="http://playerstage.sourceforge.net/gazebo/xmlschema/#interface" xmlns:sensor="http://playerstage.sourceforge.net/gazebo/xmlschema/#sensor" xmlns:xacro="http://ros.org/wiki/xacro">
  <!-- Included URDF Files -->
 
  
  <material name="light_grey">
    <color rgba="0.7 0.7 0.7 1"/>
  </material>
  <material name="dark_grey">
    <color rgba="0.5 0.5 0.5 1"/>
  </material>
  <material name="black">
    <color rgba="0 0 0 1"/>
  </material>
  <material name="almost_black">
    <color rgba="0.1 0.1 0.1 1"/>
  </material>
  <material name="arm_material">
    <color rgba="0.6 0.6 0.6 1"/>
  </material>
  <material name="original_arm_material">
    <color rgba="0.79216 0.81961 0.93333 1" />
  </material>
  
  
  <!-- Add the segbot base -->
  <link name="base_footprint">
    <visual>
      <origin rpy="0 0 0" xyz="0 0 0"/>
      <geometry>
        <box size="0.001 0.001 0.001"/>
      </geometry>
    </visual>
  </link>

   <!-- kinnect -->
  <joint name="nav_kinect_joint" type="fixed">
    <origin rpy="3.14 3 .75" xyz="0.7 0.7 0.7"/>
    <parent link="base_footprint"/>
    <child link="nav_kinect_link"/>
  </joint>
  <link name="nav_kinect_link">
    <inertial>
      <mass value="0.1"/>
      <origin rpy="0 0 0" xyz="0 0 0"/>
      <inertia ixx="0.01" ixy="0.0" ixz="0.0" iyy="0.01" iyz="0.0" izz="0.01"/>
    </inertial>
    <visual>
      <origin rpy="0 0 0" xyz="0.0 0.012 0"/>
      <geometry>
        <mesh filename="package://segbot_description/meshes/kinect.dae" scale="1 1 1"/>
      </geometry>
    </visual>
    <!-- <collision> -->
    <!--   <origin xyz="0.0 0.012 0" rpy="0 0 0"/> -->
    <!--   <geometry> -->
    <!--     <mesh filename="package://pr2_description/meshes/sensors/kinect_v0/kinect.dae" scale="0.001 0.001 0.001" /> -->
    <!--   </geometry> -->
    <!-- </collision> -->
  </link>
  <gazebo reference="nav_kinect_link">
    <sensor name="nav_kinect_link_sensor" type="depth">
      <always_on>true</always_on>
      <update_rate>20.0</update_rate>
      <camera>
        <horizontal_fov>0.994837673637</horizontal_fov>
        <image>
          <format>R8G8B8</format>
          <width>640</width>
          <height>480</height>
        </image>
        <clip>
          <near>0.01</near>
          <far>5</far>
        </clip>
      </camera>
      <plugin filename="libgazebo_ros_openni_kinect.so" name="nav_kinect_frame_controller">
        <alwaysOn>true</alwaysOn>
        <updateRate>20.0</updateRate>
        <cameraName>nav_kinect</cameraName>
        <imageTopicName>rgb/image_raw</imageTopicName>
        <cameraInfoTopicName>rgb/camera_info</cameraInfoTopicName>
        <depthImageTopicName>depth/image_raw</depthImageTopicName>
        <depthImageCameraInfoTopicName>depth/camera_info</depthImageCameraInfoTopicName>
        <pointCloudTopicName>depth/points</pointCloudTopicName>
        <frameName>nav_kinect_depth_optical_frame</frameName>
        <pointCloudCutoff>0.5</pointCloudCutoff>
        <distortionK1>0.00000001</distortionK1>
        <distortionK2>0.00000001</distortionK2>
        <distortionK3>0.00000001</distortionK3>
        <distortionT1>0.00000001</distortionT1>
        <distortionT2>0.00000001</distortionT2>
      </plugin>
    </sensor>
  </gazebo>
  <joint name="nav_kinect_link_joint1" type="fixed">
    <origin rpy="-1.0 0.0 -1.567" xyz="0 0 0"/>
    <parent link="nav_kinect_link"/>
    <child link="camera_rgb_optical_frame"/>
  </joint>
  <link name="camera_rgb_optical_frame">
    <inertial>
      <mass value="0.001"/>
      <origin rpy="0 0 0" xyz="0 0 0"/>
      <inertia ixx="0.0001" ixy="0" ixz="0" iyy="0.000001" iyz="0" izz="0.0001"/>
    </inertial>
  </link>
  
  <link
    name="Shoulder_Link">
    <inertial>
      <origin
        xyz="9.8364E-07 0.014125 0.070452"
        rpy="0 0 0" />
      <mass
        value="0.76" />
      <inertia
        ixx="0.00044618"
        ixy="-2.0592E-08"
        ixz="-9.2286E-09"
        iyy="0.00047056"
        iyz="-7.4063E-05"
        izz="0.00019269" />
    </inertial>
    <visual>
      <origin
        xyz="0 0 0"
        rpy="0 0 0" />
      <geometry>
        <mesh
          filename="package://jaco_model/meshes/mico_alt/Shoulder_Link.STL" />
      </geometry>
      <material name="arm_material"/>
        
    </visual>
    <collision>
      <origin
        xyz="0 0 0"
        rpy="0 0 0" />
      <geometry>
        <mesh
          filename="package://jaco_model/meshes/mico_alt/Shoulder_Link.STL" />
      </geometry>
    </collision>
  </link>
  
  <joint
    name="Shoulder_Joint"
    type="revolute">
    <origin rpy="3.1416 0 3.1416" xyz="0.0 0 0.18"/>
    <parent
      link="base_footprint" />
    <child
      link="Shoulder_Link" />
    <axis
      xyz="0 0 1" />
    <limit
      lower="-3.14"
      upper="3.14"
      effort="0"
      velocity="0" />
  </joint>
 
  <link
    name="Arm_Link">
    <inertial>
      <origin
        xyz="-1.5264E-05 0.13777 -0.021034"
        rpy="0 0 0" />
      <mass
        value="0.76" />
      <inertia
        ixx="0.0036974"
        ixy="-7.8568E-08"
        ixz="4.7633E-08"
        iyy="0.00022818"
        iyz="-5.7314E-05"
        izz="0.0038268" />
    </inertial>
    <visual>
      <origin
        xyz="0 0 0"
        rpy="0 0 0" />
      <geometry>
        <mesh
          filename="package://jaco_model/meshes/mico_alt/Arm_Link.STL" />
      </geometry>
       <material name="arm_material"/>
    </visual>
    <collision>
      <origin
        xyz="0 0 0"
        rpy="0 0 0" />
      <geometry>
        <mesh
          filename="package://jaco_model/meshes/mico_alt/Arm_Link.STL" />
      </geometry>
    </collision>
  </link>
  <joint
    name="Arm_Joint"
    type="revolute">
    <origin
      xyz="0 -0.00625 -0.12325"
      rpy="-1.5708 4.3794E-14 0" />
    <parent
      link="Shoulder_Link" />
    <child
      link="Arm_Link" />
    <axis
      xyz="0 0 1" />
    <limit
      lower="-2.26"
      upper="2.26"
      effort="0"
      velocity="0" />
  </joint>
  
  <link
    name="Forearm_Link">
    <inertial>
      <origin
        xyz="3.3265E-06 0.035568 -0.023918"
        rpy="0 0 0" />
      <mass
        value="0.4" />
      <inertia
        ixx="0.00029276"
        ixy="2.9256E-08"
        ixz="4.5147E-08"
        iyy="0.00011211"
        iyz="1.2704E-05"
        izz="0.00033531" />
    </inertial>
    <visual>
      <origin
        xyz="0 0 0"
        rpy="0 0 0" />
      <geometry>
        <mesh
          filename="package://jaco_model/meshes/mico_alt/Forearm_Link.STL" />
      </geometry>
       <material name="arm_material"/>
    </visual>
    <collision>
      <origin
        xyz="0 0 0"
        rpy="0 0 0" />
      <geometry>
        <mesh
          filename="package://jaco_model/meshes/mico_alt/Forearm_Link.STL" />
      </geometry>
    </collision>
  </link>
  <joint
    name="Forearm_Joint"
    type="revolute">
    <origin
      xyz="0 0.29 0"
      rpy="3.1416 0 3.1416" />
    <parent
      link="Arm_Link" />
    <child
      link="Forearm_Link" />
    <axis
      xyz="0 0 -1" />
    <limit
      lower="-2.44"
      upper="2.44"
      effort="0"
      velocity="0" />
  </joint>
  <link
    name="Wrist_1_Link">
    <inertial>
      <origin
        xyz="-3.8615E-05 0.0067766 -0.027417"
        rpy="0 0 0" />
      <mass
        value="0.4" />
      <inertia
        ixx="4.9442E-05"
        ixy="-2.5359E-08"
        ixz="2.3947E-08"
        iyy="4.949E-05"
        iyz="-5.6364E-06"
        izz="4.0284E-05" />
    </inertial>
    <visual>
      <origin
        xyz="0 0 0"
        rpy="0 0 0" />
      <geometry>
        <mesh
          filename="package://jaco_model/meshes/mico_alt/Wrist_1_Link.STL" />
      </geometry>
       <material name="arm_material"/>
    </visual>
    <collision>
      <origin
        xyz="0 0 0"
        rpy="0 0 0" />
      <geometry>
        <mesh
          filename="package://jaco_model/meshes/mico_alt/Wrist_1_Link.STL" />
      </geometry>
    </collision>
  </link>
  <joint
    name="Wrist_1_Joint"
    type="revolute">
    <origin
      xyz="0 0.127 -0.01325"
      rpy="1.5708 -2.3904E-31 6.8996E-15" />
    <parent
      link="Forearm_Link" />
    <child
      link="Wrist_1_Link" />
    <axis
      xyz="0 0 -1" />
    <limit
      lower="-3.14"
      upper="3.14"
      effort="0"
      velocity="0" />
  </joint>
  
  <link
    name="Wrist_2_Link">
    <inertial>
      <origin
        xyz="3.8855E-05 -0.006776 -0.027417"
        rpy="0 0 0" />
      <mass
        value="0.4" />
      <inertia
        ixx="4.9444E-05"
        ixy="-2.4795E-08"
        ixz="-2.4072E-08"
        iyy="4.949E-05"
        iyz="5.635E-06"
        izz="4.0281E-05" />
    </inertial>
    <visual>
      <origin
        xyz="0 0 0"
        rpy="0 0 0" />
      <geometry>
        <mesh
          filename="package://jaco_model/meshes/mico_alt/Wrist_2_Link.STL" />
      </geometry>
       <material name="arm_material"/>
    </visual>
    <collision>
      <origin
        xyz="0 0 0"
        rpy="0 0 0" />
      <geometry>
        <mesh
          filename="package://jaco_model/meshes/mico_alt/Wrist_2_Link.STL" />
      </geometry>
    </collision>
  </link>
  <joint
    name="Wrist_2_Joint"
    type="revolute">
    <origin
      xyz="0 0.040276 -0.062261"
      rpy="1.0472 -1.1202E-14 -7.4515E-15" />
    <parent
      link="Wrist_1_Link" />
    <child
      link="Wrist_2_Link" />
    <axis
      xyz="0 0 -1" />
    <limit
      lower="-3.14"
      upper="3.14"
      effort="0"
      velocity="0" />
  </joint>
  <link
    name="Hand_Link">
    <inertial>
      <origin
        xyz="-0.0014195 7.8354E-06 -0.066076"
        rpy="0 0 0" />
      <mass
        value="0.4" />
      <inertia
        ixx="0.00025595"
        ixy="-1.199E-08"
        ixz="4.5804E-06"
        iyy="0.00020193"
        iyz="5.0676E-08"
        izz="0.00013393" />
    </inertial>
    <visual>
      <origin
        xyz="0 0 0"
        rpy="0 0 0" />
      <geometry>
        <mesh
          filename="package://jaco_model/meshes/mico_alt/Hand_Link.STL" />
      </geometry>
       <material name="arm_material"/>
    </visual>
    <collision>
      <origin
        xyz="0 0 0"
        rpy="0 0 0" />
      <geometry>
        <mesh
          filename="package://jaco_model/meshes/mico_alt/Hand_Link.STL" />
      </geometry>
    </collision>
  </link>
  <joint
    name="Hand_Joint"
    type="revolute">
    <origin
      xyz="0 -0.040276 -0.062261"
      rpy="-1.0472 4.7648E-15 6.6501E-15" />
    <parent
      link="Wrist_2_Link" />
    <child
      link="Hand_Link" />
    <axis
      xyz="0 0 1" />
    <limit
      lower="-3.14"
      upper="3.14"
      effort="0"
      velocity="0" />
  </joint>
  <link
    name="Finger_1_Proximal_Link">
    <inertial>
      <origin
        xyz="0.0172616572113394 0.0105538611465319 -0.0112506191776746"
        rpy="0 0 0" />
      <mass
        value="0.0106365214895162" />
      <inertia
        ixx="2.41074761126296E-06"
        ixy="6.22421954028106E-07"
        ixz="-2.46521467551818E-11"
        iyy="1.51566092378154E-06"
        iyz="4.24681773393991E-11"
        izz="2.54988112393165E-06" />
    </inertial>
    <visual>
      <origin
        xyz="0 0 0"
        rpy="0 0 0" />
      <geometry>
        <mesh
          filename="package://jaco_model/meshes/mico_alt/Finger_1_Proximal_Link.STL" />
      </geometry>
      <material name="arm_material"/>
    </visual>
    <collision>
      <origin
        xyz="0 0 0"
        rpy="0 0 0" />
      <geometry>
        <mesh
          filename="package://jaco_model/meshes/mico_alt/Finger_1_Proximal_Link.STL" />
      </geometry>
    </collision>
  </link>
  <joint
    name="Finger_1_Proximal_Joint"
    type="revolute">
    <origin
      xyz="-0.013746 0.030948 -0.11107"
      rpy="-1.5708 3.3457E-16 1.5708" />
    <parent
      link="Hand_Link" />
    <child
      link="Finger_1_Proximal_Link" />
    <axis
      xyz="0 0 1" />
    <limit
      lower="0"
      upper="0.78"
      effort="0"
      velocity="0" />
  </joint>
  <link
    name="Finger_1_Distal_Link">
    <inertial>
      <origin
        xyz="0.0126210373400246 0.00643480436760779 -0.0112500681940836"
        rpy="0 0 0" />
      <mass
        value="0.0121939442358921" />
      <inertia
        ixx="1.65156773375087E-06"
        ixy="9.54167272729886E-07"
        ixz="-1.00860347569415E-11"
        iyy="1.49606028082548E-06"
        iyz="-1.22490314303896E-11"
        izz="2.37956623675183E-06" />
    </inertial>
    <visual>
      <origin
        xyz="0 0 0"
        rpy="0 0 0" />
      <geometry>
        <mesh
          filename="package://jaco_model/meshes/mico_alt/Finger_1_Distal_Link.STL" />
      </geometry>
       <material name="arm_material"/>
    </visual>
    <collision>
      <origin
        xyz="0 0 0"
        rpy="0 0 0" />
      <geometry>
        <mesh
          filename="package://jaco_model/meshes/mico_alt/Finger_1_Distal_Link.STL" />
      </geometry>
    </collision>
  </link>
  <joint
    name="Finger_1_Distal_Joint"
    type="revolute">
    <origin
      xyz="0.026055 0.035582 0"
      rpy="-4.0279E-17 6.1154E-17 -4.7179E-31" />
    <parent
      link="Finger_1_Proximal_Link" />
    <child
      link="Finger_1_Distal_Link" />
    <axis
      xyz="0 0 1" />
    <limit
      lower="0"
      upper="0.78"
      effort="0"
      velocity="0" />
  </joint>
  <link
    name="Finger_2_Proximal_Link">
    <inertial>
      <origin
        xyz="-0.0172616584345737 -0.0105538552511416 0.0112493808527515"
        rpy="0 0 0" />
      <mass
        value="0.0106365251828778" />
      <inertia
        ixx="2.41074854318984E-06"
        ixy="6.22421733493864E-07"
        ixz="2.47092382285307E-11"
        iyy="1.51566070025321E-06"
        iyz="-4.24941314480507E-11"
        izz="2.54988230315087E-06" />
    </inertial>
    <visual>
      <origin
        xyz="0 0 0"
        rpy="0 0 0" />
      <geometry>
        <mesh
          filename="package://jaco_model/meshes/mico_alt/Finger_2_Proximal_Link.STL" />
      </geometry>
      <material name="arm_material"/>
    </visual>
    <collision>
      <origin
        xyz="0 0 0"
        rpy="0 0 0" />
      <geometry>
        <mesh
          filename="package://jaco_model/meshes/mico_alt/Finger_2_Proximal_Link.STL" />
      </geometry>
    </collision>
  </link>
  <joint
    name="Finger_2_Proximal_Joint"
    type="revolute">
    <origin
      xyz="-0.013746 -0.030948 -0.11107"
      rpy="1.5708 3.3457E-16 1.5708" />
    <parent
      link="Hand_Link" />
    <child
      link="Finger_2_Proximal_Link" />
    <axis
      xyz="0 0 1" />
    <limit
      lower="0"
      upper="0.78"
      effort="0"
      velocity="0" />
  </joint>
  <link
    name="Finger_2_Distal_Link">
    <inertial>
      <origin
        xyz="-0.0126210373425155 -0.00643480437565225 0.0112499318045061"
        rpy="0 0 0" />
      <mass
        value="0.012193944229752" />
      <inertia
        ixx="1.65156773202737E-06"
        ixy="9.54167272215506E-07"
        ixz="1.00859417239942E-11"
        iyy="1.49606028060199E-06"
        iyz="1.22487380227665E-11"
        izz="2.37956623494218E-06" />
    </inertial>
    <visual>
      <origin
        xyz="0 0 0"
        rpy="0 0 0" />
      <geometry>
        <mesh
          filename="package://jaco_model/meshes/mico_alt/Finger_2_Distal_Link.STL" />
      </geometry>
      <material name="arm_material"/>
    </visual>
    <collision>
      <origin
        xyz="0 0 0"
        rpy="0 0 0" />
      <geometry>
        <mesh
          filename="package://jaco_model/meshes/mico_alt/Finger_2_Distal_Link.STL" />
      </geometry>
    </collision>
  </link>
  <joint
    name="Finger_2_Distal_Joint"
    type="revolute">
    <origin
      xyz="-0.026055 -0.035582 0"
      rpy="4.8081E-17 -4.6577E-17 -5.6023E-31" />
    <parent
      link="Finger_2_Proximal_Link" />
    <child
      link="Finger_2_Distal_Link" />
    <axis
      xyz="0 0 1" />
    <limit
      lower="0"
      upper="0.78"
      effort="0"
      velocity="0" />
  </joint>
  
  <joint name="arm_base_cyl" type="fixed">
    <origin rpy="0 0 0" xyz="0.0 0.0 0.09"/>
    <parent link="base_footprint"/>
    <child link="arm_base_cyl_link"/>
  </joint>
  <link name="arm_base_cyl_link">
    <inertial>
      <mass value="0.1"/>
      <origin rpy="0 0 0" xyz="0 0 0"/>
      <inertia ixx="0.01" ixy="0.0" ixz="0.0" iyy="0.01" iyz="0.0" izz="0.01"/>
    </inertial>
    <visual>
      <origin rpy="0 0 0" xyz="0 0 0.009525"/>
      <geometry>
        <cylinder length="0.18" radius="0.0425"/>
      </geometry>
      <material name="arm_material"/>
    </visual>
    <collision>
      <origin rpy="0 0 0" xyz="0 0 0.009525"/>
      <geometry>
        <cylinder length="0.18" radius="0.02"/>
      </geometry>
    </collision>
  </link>
  <gazebo reference="arm_base_cyl_link">
    <material>Gazebo/Grey</material>
    <mu1 value="100.0"/>
    <mu2 value="100.0"/>
    <kp value="1000000.0"/>
    <kd value="1.0"/>
  </gazebo>
  
  
</robot>


